<?xml version="1.0" encoding="UTF-8"?>
<!-- Generated by org.testng.reporters.JUnitXMLReporter -->
<testsuite hostname="BGLRT4700515" name="Default test" tests="4" failures="1" timestamp="12 Nov 2021 11:59:32 GMT" time="53.805" errors="0">
  <testcase name="TC010_ReadHeading" time="6.384" classname="testcases.Assignment_10To12"/>
  <testcase name="TC011_12_RetryAnalyzer" time="0.005" classname="testcases.Assignment_10To12">
    <skipped/>
  </testcase> <!-- TC011_12_RetryAnalyzer -->
  <testcase name="TC011_12_RetryAnalyzer" time="0.003" classname="testcases.Assignment_10To12">
    <skipped/>
  </testcase> <!-- TC011_12_RetryAnalyzer -->
  <testcase name="TC011_12_RetryAnalyzer" time="0.008" classname="testcases.Assignment_10To12">
    <failure type="java.lang.AssertionError" message="Failing Intentionally: expected [true] but found [false]">
      <![CDATA[java.lang.AssertionError: Failing Intentionally: expected [true] but found [false]
	at org.testng.Assert.fail(Assert.java:94)
	at org.testng.Assert.failNotEquals(Assert.java:513)
	at org.testng.Assert.assertEqualsImpl(Assert.java:135)
	at org.testng.Assert.assertEquals(Assert.java:116)
	at org.testng.Assert.assertEquals(Assert.java:305)
	at testcases.Assignment_10To12.TC011_12_RetryAnalyzer(Assignment_10To12.java:60)
	at sun.reflect.NativeMethodAccessorImpl.invoke0(Native Method)
	at sun.reflect.NativeMethodAccessorImpl.invoke(Unknown Source)
	at sun.reflect.DelegatingMethodAccessorImpl.invoke(Unknown Source)
	at java.lang.reflect.Method.invoke(Unknown Source)
	at org.testng.internal.MethodInvocationHelper.invokeMethod(MethodInvocationHelper.java:86)
	at org.testng.internal.Invoker.invokeMethod(Invoker.java:645)
	at org.testng.internal.Invoker.retryFailed(Invoker.java:969)
	at org.testng.internal.Invoker.invokeTestMethods(Invoker.java:1148)
	at org.testng.internal.TestMethodWorker.invokeTestMethods(TestMethodWorker.java:129)
	at org.testng.internal.TestMethodWorker.run(TestMethodWorker.java:112)
	at org.testng.TestRunner.privateRun(TestRunner.java:782)
	at org.testng.TestRunner.run(TestRunner.java:632)
	at org.testng.SuiteRunner.runTest(SuiteRunner.java:366)
	at org.testng.SuiteRunner.runSequentially(SuiteRunner.java:361)
	at org.testng.SuiteRunner.privateRun(SuiteRunner.java:319)
	at org.testng.SuiteRunner.run(SuiteRunner.java:268)
	at org.testng.SuiteRunnerWorker.runSuite(SuiteRunnerWorker.java:52)
	at org.testng.SuiteRunnerWorker.run(SuiteRunnerWorker.java:86)
	at org.testng.TestNG.runSuitesSequentially(TestNG.java:1244)
	at org.testng.TestNG.runSuitesLocally(TestNG.java:1169)
	at org.testng.TestNG.run(TestNG.java:1064)
	at org.testng.remote.RemoteTestNG.run(RemoteTestNG.java:113)
	at org.testng.remote.RemoteTestNG.initAndRun(RemoteTestNG.java:206)
	at org.testng.remote.RemoteTestNG.main(RemoteTestNG.java:177)
]]>
    </failure>
  </testcase> <!-- TC011_12_RetryAnalyzer -->
</testsuite> <!-- Default test -->
