<?xml version="1.0" encoding="UTF-8"?>
<testng-results skipped="2" failed="1" total="4" passed="1">
  <reporter-output>
  </reporter-output>
  <suite name="Default suite" duration-ms="53805" started-at="2021-11-12T11:58:38Z" finished-at="2021-11-12T11:59:32Z">
    <groups>
    </groups>
    <test name="Default test" duration-ms="53805" started-at="2021-11-12T11:58:38Z" finished-at="2021-11-12T11:59:32Z">
      <class name="testcases.Assignment_10To12">
        <test-method status="PASS" signature="Setup()[pri:0, instance:testcases.Assignment_10To12@26f67b76]" name="Setup" is-config="true" duration-ms="10679" started-at="2021-11-12T17:28:38Z" finished-at="2021-11-12T17:28:49Z">
          <reporter-output>
          </reporter-output>
        </test-method> <!-- Setup -->
        <test-method status="PASS" signature="TC010_ReadHeading()[pri:0, instance:testcases.Assignment_10To12@26f67b76]" name="TC010_ReadHeading" duration-ms="6384" started-at="2021-11-12T17:28:49Z" finished-at="2021-11-12T17:28:55Z">
          <reporter-output>
          </reporter-output>
        </test-method> <!-- TC010_ReadHeading -->
        <test-method status="PASS" signature="closeApps()[pri:0, instance:testcases.Assignment_10To12@26f67b76]" name="closeApps" is-config="true" duration-ms="917" started-at="2021-11-12T17:28:59Z" finished-at="2021-11-12T17:29:00Z">
          <reporter-output>
          </reporter-output>
        </test-method> <!-- closeApps -->
        <test-method status="PASS" signature="Setup()[pri:0, instance:testcases.Assignment_10To12@26f67b76]" name="Setup" is-config="true" duration-ms="8337" started-at="2021-11-12T17:29:00Z" finished-at="2021-11-12T17:29:08Z">
          <reporter-output>
          </reporter-output>
        </test-method> <!-- Setup -->
        <test-method status="SKIP" signature="TC011_12_RetryAnalyzer()[pri:0, instance:testcases.Assignment_10To12@26f67b76]" name="TC011_12_RetryAnalyzer" duration-ms="5" started-at="2021-11-12T17:29:08Z" finished-at="2021-11-12T17:29:08Z">
          <exception class="java.lang.AssertionError">
            <message>
              <![CDATA[Failing Intentionally: expected [true] but found [false]]]>
            </message>
            <full-stacktrace>
              <![CDATA[java.lang.AssertionError: Failing Intentionally: expected [true] but found [false]
	at org.testng.Assert.fail(Assert.java:94)
	at org.testng.Assert.failNotEquals(Assert.java:513)
	at org.testng.Assert.assertEqualsImpl(Assert.java:135)
	at org.testng.Assert.assertEquals(Assert.java:116)
	at org.testng.Assert.assertEquals(Assert.java:305)
	at testcases.Assignment_10To12.TC011_12_RetryAnalyzer(Assignment_10To12.java:60)
	at sun.reflect.NativeMethodAccessorImpl.invoke0(Native Method)
	at sun.reflect.NativeMethodAccessorImpl.invoke(Unknown Source)
	at sun.reflect.DelegatingMethodAccessorImpl.invoke(Unknown Source)
	at java.lang.reflect.Method.invoke(Unknown Source)
	at org.testng.internal.MethodInvocationHelper.invokeMethod(MethodInvocationHelper.java:86)
	at org.testng.internal.Invoker.invokeMethod(Invoker.java:645)
	at org.testng.internal.Invoker.invokeTestMethod(Invoker.java:822)
	at org.testng.internal.Invoker.invokeTestMethods(Invoker.java:1130)
	at org.testng.internal.TestMethodWorker.invokeTestMethods(TestMethodWorker.java:129)
	at org.testng.internal.TestMethodWorker.run(TestMethodWorker.java:112)
	at org.testng.TestRunner.privateRun(TestRunner.java:782)
	at org.testng.TestRunner.run(TestRunner.java:632)
	at org.testng.SuiteRunner.runTest(SuiteRunner.java:366)
	at org.testng.SuiteRunner.runSequentially(SuiteRunner.java:361)
	at org.testng.SuiteRunner.privateRun(SuiteRunner.java:319)
	at org.testng.SuiteRunner.run(SuiteRunner.java:268)
	at org.testng.SuiteRunnerWorker.runSuite(SuiteRunnerWorker.java:52)
	at org.testng.SuiteRunnerWorker.run(SuiteRunnerWorker.java:86)
	at org.testng.TestNG.runSuitesSequentially(TestNG.java:1244)
	at org.testng.TestNG.runSuitesLocally(TestNG.java:1169)
	at org.testng.TestNG.run(TestNG.java:1064)
	at org.testng.remote.RemoteTestNG.run(RemoteTestNG.java:113)
	at org.testng.remote.RemoteTestNG.initAndRun(RemoteTestNG.java:206)
	at org.testng.remote.RemoteTestNG.main(RemoteTestNG.java:177)
]]>
            </full-stacktrace>
          </exception> <!-- java.lang.AssertionError -->
          <reporter-output>
          </reporter-output>
        </test-method> <!-- TC011_12_RetryAnalyzer -->
        <test-method status="PASS" signature="closeApps()[pri:0, instance:testcases.Assignment_10To12@26f67b76]" name="closeApps" is-config="true" duration-ms="933" started-at="2021-11-12T17:29:08Z" finished-at="2021-11-12T17:29:09Z">
          <reporter-output>
          </reporter-output>
        </test-method> <!-- closeApps -->
        <test-method status="PASS" signature="Setup()[pri:0, instance:testcases.Assignment_10To12@26f67b76]" name="Setup" is-config="true" duration-ms="8408" started-at="2021-11-12T17:29:09Z" finished-at="2021-11-12T17:29:18Z">
          <reporter-output>
          </reporter-output>
        </test-method> <!-- Setup -->
        <test-method status="SKIP" signature="TC011_12_RetryAnalyzer()[pri:0, instance:testcases.Assignment_10To12@26f67b76]" name="TC011_12_RetryAnalyzer" duration-ms="3" started-at="2021-11-12T17:29:18Z" finished-at="2021-11-12T17:29:18Z">
          <exception class="java.lang.AssertionError">
            <message>
              <![CDATA[Failing Intentionally: expected [true] but found [false]]]>
            </message>
            <full-stacktrace>
              <![CDATA[java.lang.AssertionError: Failing Intentionally: expected [true] but found [false]
	at org.testng.Assert.fail(Assert.java:94)
	at org.testng.Assert.failNotEquals(Assert.java:513)
	at org.testng.Assert.assertEqualsImpl(Assert.java:135)
	at org.testng.Assert.assertEquals(Assert.java:116)
	at org.testng.Assert.assertEquals(Assert.java:305)
	at testcases.Assignment_10To12.TC011_12_RetryAnalyzer(Assignment_10To12.java:60)
	at sun.reflect.NativeMethodAccessorImpl.invoke0(Native Method)
	at sun.reflect.NativeMethodAccessorImpl.invoke(Unknown Source)
	at sun.reflect.DelegatingMethodAccessorImpl.invoke(Unknown Source)
	at java.lang.reflect.Method.invoke(Unknown Source)
	at org.testng.internal.MethodInvocationHelper.invokeMethod(MethodInvocationHelper.java:86)
	at org.testng.internal.Invoker.invokeMethod(Invoker.java:645)
	at org.testng.internal.Invoker.retryFailed(Invoker.java:969)
	at org.testng.internal.Invoker.invokeTestMethods(Invoker.java:1148)
	at org.testng.internal.TestMethodWorker.invokeTestMethods(TestMethodWorker.java:129)
	at org.testng.internal.TestMethodWorker.run(TestMethodWorker.java:112)
	at org.testng.TestRunner.privateRun(TestRunner.java:782)
	at org.testng.TestRunner.run(TestRunner.java:632)
	at org.testng.SuiteRunner.runTest(SuiteRunner.java:366)
	at org.testng.SuiteRunner.runSequentially(SuiteRunner.java:361)
	at org.testng.SuiteRunner.privateRun(SuiteRunner.java:319)
	at org.testng.SuiteRunner.run(SuiteRunner.java:268)
	at org.testng.SuiteRunnerWorker.runSuite(SuiteRunnerWorker.java:52)
	at org.testng.SuiteRunnerWorker.run(SuiteRunnerWorker.java:86)
	at org.testng.TestNG.runSuitesSequentially(TestNG.java:1244)
	at org.testng.TestNG.runSuitesLocally(TestNG.java:1169)
	at org.testng.TestNG.run(TestNG.java:1064)
	at org.testng.remote.RemoteTestNG.run(RemoteTestNG.java:113)
	at org.testng.remote.RemoteTestNG.initAndRun(RemoteTestNG.java:206)
	at org.testng.remote.RemoteTestNG.main(RemoteTestNG.java:177)
]]>
            </full-stacktrace>
          </exception> <!-- java.lang.AssertionError -->
          <reporter-output>
          </reporter-output>
        </test-method> <!-- TC011_12_RetryAnalyzer -->
        <test-method status="PASS" signature="closeApps()[pri:0, instance:testcases.Assignment_10To12@26f67b76]" name="closeApps" is-config="true" duration-ms="942" started-at="2021-11-12T17:29:18Z" finished-at="2021-11-12T17:29:19Z">
          <reporter-output>
          </reporter-output>
        </test-method> <!-- closeApps -->
        <test-method status="PASS" signature="Setup()[pri:0, instance:testcases.Assignment_10To12@26f67b76]" name="Setup" is-config="true" duration-ms="8325" started-at="2021-11-12T17:29:19Z" finished-at="2021-11-12T17:29:27Z">
          <reporter-output>
          </reporter-output>
        </test-method> <!-- Setup -->
        <test-method status="FAIL" signature="TC011_12_RetryAnalyzer()[pri:0, instance:testcases.Assignment_10To12@26f67b76]" name="TC011_12_RetryAnalyzer" duration-ms="8" started-at="2021-11-12T17:29:27Z" finished-at="2021-11-12T17:29:27Z">
          <exception class="java.lang.AssertionError">
            <message>
              <![CDATA[Failing Intentionally: expected [true] but found [false]]]>
            </message>
            <full-stacktrace>
              <![CDATA[java.lang.AssertionError: Failing Intentionally: expected [true] but found [false]
	at org.testng.Assert.fail(Assert.java:94)
	at org.testng.Assert.failNotEquals(Assert.java:513)
	at org.testng.Assert.assertEqualsImpl(Assert.java:135)
	at org.testng.Assert.assertEquals(Assert.java:116)
	at org.testng.Assert.assertEquals(Assert.java:305)
	at testcases.Assignment_10To12.TC011_12_RetryAnalyzer(Assignment_10To12.java:60)
	at sun.reflect.NativeMethodAccessorImpl.invoke0(Native Method)
	at sun.reflect.NativeMethodAccessorImpl.invoke(Unknown Source)
	at sun.reflect.DelegatingMethodAccessorImpl.invoke(Unknown Source)
	at java.lang.reflect.Method.invoke(Unknown Source)
	at org.testng.internal.MethodInvocationHelper.invokeMethod(MethodInvocationHelper.java:86)
	at org.testng.internal.Invoker.invokeMethod(Invoker.java:645)
	at org.testng.internal.Invoker.retryFailed(Invoker.java:969)
	at org.testng.internal.Invoker.invokeTestMethods(Invoker.java:1148)
	at org.testng.internal.TestMethodWorker.invokeTestMethods(TestMethodWorker.java:129)
	at org.testng.internal.TestMethodWorker.run(TestMethodWorker.java:112)
	at org.testng.TestRunner.privateRun(TestRunner.java:782)
	at org.testng.TestRunner.run(TestRunner.java:632)
	at org.testng.SuiteRunner.runTest(SuiteRunner.java:366)
	at org.testng.SuiteRunner.runSequentially(SuiteRunner.java:361)
	at org.testng.SuiteRunner.privateRun(SuiteRunner.java:319)
	at org.testng.SuiteRunner.run(SuiteRunner.java:268)
	at org.testng.SuiteRunnerWorker.runSuite(SuiteRunnerWorker.java:52)
	at org.testng.SuiteRunnerWorker.run(SuiteRunnerWorker.java:86)
	at org.testng.TestNG.runSuitesSequentially(TestNG.java:1244)
	at org.testng.TestNG.runSuitesLocally(TestNG.java:1169)
	at org.testng.TestNG.run(TestNG.java:1064)
	at org.testng.remote.RemoteTestNG.run(RemoteTestNG.java:113)
	at org.testng.remote.RemoteTestNG.initAndRun(RemoteTestNG.java:206)
	at org.testng.remote.RemoteTestNG.main(RemoteTestNG.java:177)
]]>
            </full-stacktrace>
          </exception> <!-- java.lang.AssertionError -->
          <reporter-output>
          </reporter-output>
        </test-method> <!-- TC011_12_RetryAnalyzer -->
        <test-method status="PASS" signature="closeApps()[pri:0, instance:testcases.Assignment_10To12@26f67b76]" name="closeApps" is-config="true" duration-ms="1303" started-at="2021-11-12T17:29:31Z" finished-at="2021-11-12T17:29:32Z">
          <reporter-output>
          </reporter-output>
        </test-method> <!-- closeApps -->
      </class> <!-- testcases.Assignment_10To12 -->
    </test> <!-- Default test -->
  </suite> <!-- Default suite -->
</testng-results>
